Workbook
Name _00: #REF!
Name _1: #REF!
Name _2: #REF!
Name ddddddddddddddddd: #REF!
Name MM: #REF!
Name MM: #REF!
Name MM개발계획10월: #REF!
Name MM개발계획10월: #REF!
Name MM개발계획11월: #REF!
Name MM개발계획11월: #REF!
Name MM개발계획12월: #REF!
Name MM개발계획12월: #REF!
Name MM개발계획12월2005: #REF!
Name MM개발계획12월2005: #REF!
Name MM개발계획1월: #REF!
Name MM개발계획1월: #REF!
Name MM개발계획2월: #REF!
Name MM개발계획2월: #REF!
Name MM개발계획3월: #REF!
Name MM개발계획3월: #REF!
Name MM개발계획4월: #REF!
Name MM개발계획4월: #REF!
Name MM개발계획5월: #REF!
Name MM개발계획5월: #REF!
Name MM개발계획6월: #REF!
Name MM개발계획6월: #REF!
Name MM개발계획7월: #REF!
Name MM개발계획7월: #REF!
Name MM개발계획8월: #REF!
Name MM개발계획8월: #REF!
Name MM개발계획9월: #REF!

Sheet _com.sap.ip.bi.xl.hiddensheet

Sheet List
B2: No. | C2: Source System | D2: Interface ID | E2: 변경 IF-ID | F2: IN/OUT | G2: 맵핑정의 ID | H2: 맵핑정의 항목 | I2: 사용처 | J2: Entity 분류 | K2: 작업유형 | L2: I/F정의서 | M2: 적용순서 | N2: I/F Table | O2: STG Table(표준화) | P2: Import Program | Q2: 비고 | S2: 쿠도개발 | V2: Aplan 구분 | W2: Source System | X2: 작업유형 | Y2: Delta/Full Data | Z2: FILE | AA2: API/File | AB2: 예상건수 | AC2: 비고 | AD2: 모듈 | AE2: 기존IF ID | AF2: 코멘트 | AG2: 유형 | AH2: 공수(M/D) | AI2: Batch Cycle | AJ2: Batch Cycle Detail | AK2: Source/Target Table Name
B3: 1 | C3: SAP | D3: SDI4012 | E3: SDI8361 | F3: INBOUND | G3: CP-03 | H3: 조직도 | I3: 공통 | J3: M | K3: 유지 | L3: Y | M3: 1 | N3: ALIFCI_OGCH_MSTR | O3: ALCDCM_OGCH_MSTR | P3: SP_STGCM_OGCH_MSTR | S3: 45967 | V3: 공통 | W3: SAP | X3: 유지 | Y3: Delta | AA3: API | AD3: SD | AE3: SDI4012 CP-03.조직도 | AF3: 확장 | AG3: 유지 | AH3: 1 | AI3: W | AJ3: Random | AK3: ZSD_SEND_ORG_01
B4: 2 | C4: SAP | D4: SDI4004 | E4: SDI8362 | F4: INBOUND | G4: CP-01 | H4: 자재마스터(영업조직: CP) | I4: 공통 | J4: M | K4: 유지 | L4: Y | M4: 1 | N4: ALIFCI_MTRL_MSTR_CP | O4: ALCDCM_MTRL_MSTR ALCDCM_MTRL_MSTR_CP | P4: SP_STGCM_MTRL_MSTR_CP | V4: 공통 | W4: SAP | X4: 유지 | Y4: Delta | AA4: API | AC4: 영업조직/Item 별 속성정보 | AD4: SD | AE4: SDI4004 CP-01.자재마스터 | AF4: 필드추가 | AG4: 변경 | AH4: 3 | AI4: W,D | AJ4: 10Min | AK4: ZSD_SEND_MATERIAL_01
B5: =+B4+1 -> 3 | C5: SAP | D5: PPI2015 | E5: PPI2058 | F5: INBOUND | G5: SP-02 | H5: 자재마스터(플랜트: SP) | I5: 공통 | J5: M | K5: 유지 | L5: Y | M5: 1 | N5: ALIFCI_MTRL_MSTR_SP | O5: ALCDCM_MTRL_MSTR_SP | P5: SP_STGCM_MTRL_MSTR_SP | V5: 공통 | W5: SAP | X5: 유지 | Y5: Delta | AA5: API | AD5: PP | AE5: PPI2015 SP-02.자재 마스터 | AF5: 필드추가 | AG5: 변경 | AH5: 3 | AI5: W,D | AJ5: 15Min | AK5: ZPP_IF_MAT_SEND_SP
B6: =+B5+1 -> 4 | C6: SAP | D6: SDI4009 | E6: SDI8363 | F6: INBOUND | G6: CP-10 | H6: 자재 단가 | I6: 공통 | J6: M | K6: 유지 | L6: Y | M6: 1 | N6: ALIFCI_MTRL_UTPR | O6: ALCDCM_MTRL_UTPR | P6: SP_STGCM_MTRL_UTPR | V6: 공통 | W6: SAP | X6: 유지 | Y6: Delta | AA6: API | AC6: 판가 정보 | AD6: SD | AE6: SDI4009 CP-10.자재 단가 | AF6: 확장 | AG6: 유지 | AH6: 1 | AI6: W,D | AJ6: 10Min | AK6: ZSD_SEND_CHANNEL_PRICE
B7: =+B6+1 -> 5 | C7: NPD | D7: PPI2027 | E7: PPI2059 | F7: INBOUND | G7: CP-25 | H7: NPD 자재 목록 | I7: 공통 | J7: M | K7: 유지 | L7: Y | M7: 2 | N7: ALIFCI_DVLP_MTRL | O7: ALCDCM_DVLP_MTRL | P7: SP_STGCM_DVLP_MTRL | V7: 공통 | W7: NPD | X7: 유지 | Y7: Full | AA7: API | AC7: 현행화 주기 나 대상 검토 필요, 현재 업데이트가 되고 있지 않음 | AD7: NPD | AE7: PPI2027 CP-25.NPD 자재 목록 | AF7: 필드 추가(NPD 소비자가 72P) | AG7: 변경 | AH7: 3 | AI7: W,D | AJ7: Daily | AK7: ZPL_IF_DEVHEAD_SINGLE
B8: =+B7+1 -> 6 | C8: SAP | D8: SDI4029 | E8: SDI8364 | F8: INBOUND | G8: CP-07 | H8: 제품 허가 정보 | I8: 공통 | J8: M | K8: 유지 | L8: Y | M8: 2 | N8: ALIFCI_MTRL_WARR | O8: ALCDCM_MTRL_WARR | P8: SP_STGCM_MTRL_WARR | Q8: 국가별 제품사용허가 정보 | V8: 공통 | W8: SAP | X8: 유지 | Y8: Full | AA8: API | AC8: BOD 및 SKU IN/OUT 에서 사용함 | AD8: SD | AE8: SDI4029 CP-07.제품 허가 정보 | AF8: 티움넷->SAP 허가 관리 대상 로직 확인 필요 | AG8: 변경(상) | AH8: 5 | AI8: W,D | AJ8: Daily | AK8: ZSD_SEND_CONFIRM_MAT_O9
B9: =+B8+1 -> 7 | C9: SAP | D9: PPI2025 | E9: PPI2060 | F9: INBOUND | G9: SP-15 | H9: 단종 품의 완료 상태 | I9: 공통 | J9: M | K9: 유지 | L9: Y | M9: 2 | N9: ALIFCI_BEDI_CNSN | O9: ALCDCM_BEDI_CNSN | P9: SP_STGCM_BEDI_CNSN | V9: 공통 | W9: SAP | X9: 신규 | Y9: Real Time | AA9: API | AC9: SAP에서 압축 품의 후 상태 수신 | AD9: PP | AE9: 신규 | AF9: 1) Aplan -> SAP: 자재, 생산단종월, 판매단종월 인터페이스 2) SAP에서 압축 품의 (Aplan에서 품의하지 않음) 3) SAP -> Aplan: 압축품의일(월), 압축대상분류 인터페이스 | AG9: 신규 | AH9: 5 | AI9: 15Min | AJ9: Random | AK9: TBD
B10: =+B9+1 -> 8 | C10: BW | D10: BII0229 | E10: BII0246 | F10: INBOUND | G10: CP-23 | H10: SKU 현황 | I10: 공통 | J10: M | K10: 유지 | L10: Y | M10: 2 | N10: ALIFCI_MTRL_PS | O10: ALCDCM_MTRL_PS | P10: SP_STGCM_MTRL_PS | V10: 공통 | W10: BW | X10: 유지 | Y10: Full | Z10: File | AA10: File | AB10: 6.5k | AD10: BW | AE10: BII0229 CP-23.SKU 현황 | AG10: 유지 | AH10: 1 | AI10: W,D | AJ10: Daily | AK10: ZBI_SEND_FILE_TO_O9
B11: =+B10+1 -> 9 | C11: NPD | D11: PPI2026 | E11: PPI2061 | F11: INBOUND | G11: CP-24 | H11: SKU In 일정 | I11: 공통 | J11: M | K11: 유지 | L11: Y | M11: 2 | N11: ALIFCI_MTRL_LNCH_SCH | O11: ALCDCM_MTRL_LNCH_SCH | P11: SP_STGCM_MTRL_LNCH_SCH | V11: 공통 | W11: NPD | X11: 유지 | Y11: Full | AA11: API | AD11: NPD | AE11: PPI2026 CP-24.SKU In 일정 | AF11: 필드 추가(NPD 생산회의 상태 68P) | AG11: 변경 | AH11: 3 | AI11: W,D | AJ11: Daily | AK11: ZPL_IF_MT_SINGLE
B12: =+B11+1 -> 10 | C12: SAP | D12: PPI2017 | E12: PPI2062 | F12: INBOUND | G12: SP-19 | H12: 자재마스터 대체단위 인터페이스 매핑구조 | I12: 공통 | J12: M | K12: 유지 | L12: Y | M12: 1 | N12: ALIFCI_MTRL_UNIT_CNVT | O12: ALCDCM_MTRL_UNIT_CNVT | P12: SP_STGCM_MTRL_UNIT_CNVT | V12: 공통 | W12: SAP | X12: 유지 | Y12: Full | AD12: PP | AE12: PPI2017 SP-19.자재마스터 대체단위 인터페이스 매핑구조 | AF12: 필드 추가 | AG12: 변경 | AH12: 3
B13: =+B12+1 -> 11 | C13: SAP | D13: PPI2011 | E13: PPI2063 | F13: INBOUND | G13: SP-13 | H13: 자재마스터 원가정보 | I13: 공통 | J13: M | K13: 유지 | L13: Y | M13: 2 | N13: ALIFCI_MTRL_PRPR | O13: ALCDCM_MTRL_PRPR | P13: SP_STGCM_MTRL_PRPR | V13: 공통 | W13: SAP | X13: 유지 | Y13: Delta | AA13: API | AC13: 해외 정보 확인 필요 | AD13: PP | AE13: PPI2011 SP-13.자재마스터 원가정보 | AG13: 유지 | AH13: 1 | AI13: D | AJ13: Daily | AK13: ZPP_IF_STD_PRICE_SEND_SP
B14: =+B13+1 -> 12 | C14: BW | D14: BII0224 | E14: BII0247 | F14: INBOUND | G14: CP-12 | H14: 재고 | I14: 공통 | J14: A | K14: 유지 | L14: Y | M14: 1 | N14: ALIFCI_INVN | O14: ALCDCA_INVN | P14: SP_STGCA_INVN | V14: 공통 | W14: BW | X14: 유지 | Y14: Full | Z14: File | AA14: File | AB14: 364k | AD14: BW | AE14: BII0224 CP-12.재고 | AG14: 유지 | AH14: 1 | AI14: D | AJ14: Daily | AK14: ZBI_SEND_FILE_TO_O9
A15: 대표다이나믹 | B15: =+B14+1 -> 13 | C15: SAP | D15: SDI4018 | E15: SDI8365 | F15: INBOUND | G15: CP-40 | H15: 재고(계획용) | I15: 공통 | J15: A | K15: 수정 | L15: Y | M15: 1 | N15: ALIFCI_INVN_PLAN | O15: ALCDCA_INVN_PLAN | P15: SP_STGCA_INVN_PLAN | Q15: 취소==> 시간차이로 다시 수정후 사용결정(11/04)이봉기=> 기존 그대로 사용하고, 주문생성후 dn미부여는 추가 인터페이스하여 활용(11/17일). | Y15: Full | Z15: File | AA15: File | AB15: 345k
B16: =+B15+1 -> 14 | C16: SAP | D16: SDI4005 | E16: SDI8366 | F16: INBOUND | G16: CP-02 | H16: 거래처마스터 | I16: DP | J16: M | K16: 유지 | L16: Y | M16: 1 | N16: ALIFCI_PRTN_MSTR | O16: ALCDCM_PRTN_MSTR | P16: SP_STGCM_PRTN_MSTR | Q16: 거래처 그룹 기준정보 필요.(데이터 존재여부) | V16: DP | W16: SAP | X16: 유지 | Y16: Delta | AA16: API | AD16: SD | AE16: SDI4005 CP-02.거래처마스터 | AG16: 유지 | AH16: 1 | AI16: W | AJ16: 15Min | AK16: ZSD_SEND_CUSTOMER_01
B17: =+B16+1 -> 15 | C17: BW | D17: BII0230 | E17: BII0248 | F17: INBOUND | G17: CP-39 | H17: SKU 목표 | I17: DP | J17: A | K17: 유지 | L17: Y | M17: 2 | N17: ALIFCI_YRLY_SAL_PLAN | O17: ALCDCA_YRLY_SAL_PLAN | P17: SP_STGCA_YRLY_SAL_PLAN | Q17: 년월+SKU 단위 판매목표수량 | V17: DP | W17: BW | X17: 유지 | Y17: Full | Z17: File | AA17: File | AB17: 3k | AD17: BW | AE17: BII0230 CP-39.SKU 목표 | AG17: 유지 | AH17: 1 | AI17: W,D | AJ17: Daily | AK17: ZBI_SEND_FILE_TO_O9
B18: =+B17+1 -> 16 | C18: BW | D18: BII0232 | E18: BII0249 | F18: INBOUND | G18: CP-42 | H18: 기준환율 | I18: DP | J18: A | K18: 유지 | L18: Y | M18: 2 | N18: ALIFCI_STND_EXRT | O18: ALCDCA_STND_EXRT | P18: SP_STGCA_STND_EXRT | Q18: 환율일자 추가가 필요하다고 판단됨 | V18: DP | W18: BW | X18: 유지 | Y18: Full | Z18: File | AA18: File | AB18: 1k | AC18: 유지(값의 정합성 확인 필요) 영업 조직별 기준환율이 I/F 되어야 함 | AD18: BW | AE18: BII0232 CP-42.기준환율 | AG18: 유지 | AH18: 1 | AI18: W,D | AJ18: Daily | AK18: ZBI_SEND_FILE_TO_O9
A19: 대표다이나믹 | B19: =+B18+1 -> 17 | C19: SAP | D19: SDI4030 | E19: SDI8367 | F19: INBOUND | G19: CP-32 | H19: 수출 진행 모니터링 | I19: DP | J19: A | K19: 유지 | L19: Y | M19: 2 | N19: ALIFCI_EXPO_PRGR_MONI | O19: ALCDCA_EXPO_PRGR_MONI | P19: SP_STGCA_EXPO_PRGR_MONI | V19: DP | W19: SAP | X19: 유지 | Y19: Full | AA19: API | AD19: SD | AE19: SDI4030 CP-32.수출 진행 모니터링 | AG19: 유지 | AH19: 1 | AI19: W,D | AJ19: Daily | AK19: ZSD_SEND_EXPORT_O9
B20: =+B19+1 -> 18 | C20: BW | D20: BII0234 | E20: BII0250 | F20: INBOUND | G20: CP-49 | H20: 거래처 재고 | I20: DP | J20: A | K20: 유지 | L20: Y | M20: 3 | N20: ALIFCI_PRTN_INVN | O20: ALCDCA_PRTN_INVN | P20: SP_STGCA_PRTN_INVN | V20: DP | W20: BW | X20: 유지 | Y20: Full | Z20: File | AA20: File | AB20: 1k | AD20: BW | AE20: BII0234 CP-49.거래처 재고 | AG20: 유지 | AH20: 1 | AI20: W,D | AJ20: Daily | AK20: ZBI_SEND_FILE_TO_O9
B21: =+B20+1 -> 19 | C21: BW | D21: BII0226 | E21: BII0251 | F21: INBOUND | G21: CP-19 | H21: 기타 수요(잡출) | I21: DP | J21: A | K21: 수정 | L21: Y | M21: 3 | N21: ALIFCI_OTH_DMD | O21: ALCDCA_OTH_DMD | P21: SP_STGCA_OTH_DMD | V21: DP | W21: BW | X21: 수정 | Y21: Full | Z21: File | AA21: File | AB21: 4.7k | AC21: Layout 변경(PG → Sold-To-Party 로 변경 | AD21: BW | AE21: BII0226 CP-19.기타 수요(잡출) | AF21: 거래처 단위 로직 변경 | AG21: 변경 | AH21: 3 | AI21: Weekly,Daily | AJ21: Daily | AK21: ZBI_SEND_FILE_TO_O9
B22: =+B21+1 -> 20 | C22: SAP | D22: PPI2003 | E22: PPI2064 | F22: INBOUND | G22: SP-01 | H22: BOM Master | I22: SP | J22: M | K22: 유지 | L22: Y | M22: 1 | N22: ALIFCI_BOM_MSTR | O22: ALCDCM_BOM_MSTR | P22: SP_STGCM_BOM_MSTR | V22: SP | W22: SAP | X22: 유지 | Y22: Delta | AA22: API | AD22: PP | AE22: PPI2003 SP-01.BOM | AF22: 신규 플랜트 로직 수정 필요 | AG22: 변경 | AH22: 3 | AI22: D | AJ22: Daily | AK22: ZPP_IF_BOM_SEND_SP
B23: =+B22+1 -> 21 | C23: SAP | D23: PPI2006 | E23: PPI2065 | F23: INBOUND | G23: SP-05 | H23: 작업장 마스터 | I23: SP | J23: M | K23: 유지 | L23: Y | M23: 1 | N23: ALIFCI_MFG_WKNS | O23: ALCDCM_MFG_WKNS | P23: SP_STGCM_MFG_WKNS | V23: SP | W23: SAP | X23: 유지 | Y23: Delta | AA23: API | AC23: (작업장 기준 Grouping 해서 Resource 로 정의 | AD23: PP | AE23: PPI2006 SP-05.작업장 마스터 | AG23: 유지 | AH23: 1 | AI23: W | AJ23: Random | AK23: ZPP_IF_WORKCENTER_SEND_SP
A24: 대표다이나믹 | B24: =+B23+1 -> 22 | C24: SAP | D24: PPI2009 | E24: PPI2066 | F24: INBOUND | G24: SP-10 | H24: 생산 오더 | I24: SP | J24: A | K24: 유지 | L24: Y | M24: 1 | N24: ALIFCI_MFG_ORD | O24: ALCDCA_MFG_ORD | P24: SP_STGCA_MFG_ORD | V24: SP | W24: SAP | X24: 유지 | Y24: Delta | AA24: API | AC24: 국내 포함 전체(해외)Plant 반영 필요 | AD24: PP | AE24: PPI2009 SP-10.생산 오더 | AG24: 변경 | AH24: 3 | AI24: W,D | AJ24: Daily | AK24: ZPP_IF_PROD_ORDER_SEND_SP
A25: 대표다이나믹 | B25: =+B24+1 -> 23 | C25: SAP | D25: PPI2010 | E25: PPI2067 | F25: INBOUND | G25: SP-11 | H25: 구매오더 | I25: SP | J25: A | K25: 유지 | L25: Y | M25: 1 | N25: ALIFCI_PUR_ORD | O25: ALCDCA_PUR_ORD | P25: SP_STGCA_PUR_ORD | V25: SP | W25: SAP | X25: 유지 | Y25: Delta | AA25: API | AC25: ODM 포함 전체 구매오더로 반영되어야 하고 확인 필요 | AD25: PP | AE25: PPI2010 SP-11.구매오더 | AG25: 유지 | AH25: 1 | AI25: W,D | AJ25: Daily | AK25: ZPP_IF_PURCH_ORDER_SEND_SP
B26: =+B25+1 -> 24 | C26: SAP | D26: PPI2004 | E26: PPI2068 | F26: INBOUND | G26: SP-03 | H26: 구매정보 (ODM 원부자재) | I26: SP | J26: M | K26: 유지 | L26: Y | M26: 2 | N26: ALIFCI_MTRL_PUR | O26: ALCDCM_MTRL_PUR | P26: SP_STGCM_MTRL_PUR | V26: SP | W26: SAP | X26: 유지 | Y26: Delta | AA26: API | AC26: ODM Network 구성 및 포장재 구매처 정의 (Category 컬럼-> 구매 또는 외주가공 정의 가능) | AD26: PP | AE26: PPI2004 SP-03.구매정보(ODM 외주 원부자재) | AG26: 유지 | AH26: 1 | AI26: W,D | AJ26: Daily | AK26: ZPP_IF_INFOREC_SEND_SP
B27: =+B26+1 -> 25 | C27: SAP | D27: PPI2005 | E27: PPI2069 | F27: INBOUND | G27: SP-04 | H27: 협력사 마스터 | I27: SP | J27: M | K27: 유지 | L27: Y | M27: 2 | N27: ALIFCI_SBCN_MSTR | O27: ALCDCM_SBCN_MSTR | P27: SP_STGCM_SBCN_MSTR | V27: SP | W27: SAP | X27: 유지 | Y27: Delta | AA27: API | AD27: PP | AE27: PPI2005 SP-04.협력사 마스터 | AG27: 유지 | AH27: 1 | AI27: W | AJ27: Daily | AK27: ZPP_IF_VENDOR_SEND_SP
B28: =+B27+1 -> 26 | C28: SAP | D28: PPI2016 | E28: PPI2070 | F28: INBOUND | G28: SP-14 | H28: 가용화 입고 실적 | I28: SP | J28: A | K28: 유지 | L28: Y | M28: 1 | N28: ALIFCI_AVAB_WRHS_PRFR | O28: ALCDCA_AVAB_WRHS_PRFR | P28: SP_STGCA_AVAB_WRHS_PRFR | V28: SP | W28: SAP | X28: 유지 | Y28: Delta | AA28: API | AC28: 엔진 Input은 아니나 활용 측면에서 검토 필요 | AD28: PP | AE28: PPI2016 SP-14.가용화 입고 실적 | AG28: 유지 | AH28: 1 | AI28: 2/Day | AJ28: 2/day( 11AM , 03PM) | AK28: ZPP_IF_AVAIL_STOCK_SEND_SP
A29: 대표다이나믹 | B29: =+B28+1 -> 27 | C29: SAP | D29: SDI4026 | E29: SDI8368 | F29: INBOUND | G29: CP-37 | H29: SOP 잔량 정보 | I29: SP | J29: A | K29: 유지 | L29: Y | M29: 1 | N29: ALIFCI_LOAD_RMN_QTY | O29: ALCDCA_LOAD_RMN_QTY | P29: SP_STGCA_LOAD_RMN_QTY | V29: SP | W29: SAP | X29: 유지 | Y29: Full | AA29: API | AC29: 선적잔량 | AD29: SC | AE29: SDI4026 CP-37.SOP 잔량 정보 | AF29: 해외요청량 프로세스 Aplan 개발 범위에 따라 공수 변동 | AG29: 유지 | AH29: 1 | AI29: W,D | AJ29: Sunday | AK29: ZSC_PIR_O9_SAP_002
B30: =+B29+1 -> 28 | C30: SAP | D30: PPI2007 | E30: PPI2071 | F30: INBOUND | G30: SP-08 | H30: 반제품 포장재 MD04 재고 | I30: SP | J30: A | K30: 유지 | L30: Y | M30: 1 | N30: ALIFCI_SMPR_INVN | O30: ALCDCA_SMPR_INVN | P30: SP_STGCA_SMPR_INVN | V30: SP | W30: SAP | X30: 유지 | Y30: Full | AA30: API | AC30: 반제품 재고 수량 + QA 수량 | AD30: PP | AE30: PPI2007 SP-08.반제품 포장재 MD04 재고 | AG30: 유지 | AH30: 1 | AI30: 2/Day | AJ30: Daily | AK30: ZPP_IF_MD04STOCK_SEND_SP
B31: =+B30+1 -> 29 | C31: IAM | D31: LEGI3532 | E31: LEGI3532 | F31: INBOUND | G31: CP-04 | H31: Role 권한 승인 정보 | I31: SYS | J31: M | K31: 유지 | L31: Y | M31: 2 | N31: ALIFCI_AUTH_ROLE | O31: ALCDCM_AUTH_ROLE | P31: SP_STGCM_AUTH_ROLE | V31: System | W31: IAM | X31: 유지 | Y31: - | AA31: API | AD31: IAM | AE31: LEGI3532 CP-04.Role 권한 승인 정보 | AF31: IAM 박소영님/레이아웃 재정의 | AG31: 변경(상) | AH31: 5 | AI31: 2/Day | AJ31: 11:30:00 AM / 04:30 PM | AK31: EX_IF_ROLE
B32: =+B31+1 -> 30 | C32: IAM | D32: LEGI3531 | E32: LEGI3531 | F32: INBOUND | G32: CP-04 | H32: 계정 승인 정보 | I32: SYS | J32: M | K32: 유지 | L32: Y | M32: 1 | N32: ALIFCI_USER_ACCT | O32: ALCDCM_USER_ACCT | P32: SP_STGCM_USER_ACCT | V32: System | W32: IAM | X32: 유지 | Y32: Delta | AA32: API | AD32: IAM | AE32: LEGI3531 CP-04. 계정 승인 정보 | AF32: IAM 박소영님/레이아웃 재정의 | AG32: 변경(상) | AH32: 5 | AI32: 2/Day | AJ32: 11:30:00 AM / 04:30 PM | AK32: EX_IF_RES_USER
B33: =+B32+1 -> 31 | C33: SAP | D33: SDI4011 | E33: SDI8369 | F33: INBOUND | G33: CP-34 | H33: CP 코드 마스터 | I33: SYS | J33: M | K33: 유지 | L33: Y | M33: 1 | N33: ALIFCI_CP_CD_MSTR | O33: ALCDCM_CP_CD_MSTR | P33: SP_STGCM_CP_CD_MSTR | Q33: SAP 공통코드 | S33: 45965 | V33: DP | W33: SAP | X33: 신규 | AD33: SD | AE33: SDI4011 CP-34.CP 코드 마스터 | AF33: 왜 신규 인터페이스인지 확인 필요 | AG33: 신규 | AH33: 5
B34: =+B33+1 -> 32 | C34: SAP | D34: SDI8354 | E34: SDI8354 | F34: INBOUND | G34: SP-41 | H34: SP-41. 저장위치리스트 | I34: 공통 | J34: M | K34: 신규 | L34: Y | N34: ALIFCI_INVN_SLOC | O34: ALCDCM_INVN_SLOC | P34: SP_STGCM_INVN_SLOC | Q34: SRC 시스템 다름 | R34: 20251020추가 | V34: SP | W34: SAP | X34: 신규
B35: =+B34+1 -> 33 | C35: SAP | D35: PPI2018 | E35: PPI2072 | F35: INBOUND | G35: SP-20 | H35: 공장달력 인터페이스 | I35: SP | J35: A | K35: 수정 | L35: Y | N35: ALIFCI_PLNT_CLD | O35: ALCDCA_PLNT_CLD | P35: SP_STGCA_PLNT_CLD | R35: 20251020추가 | V35: SP | W35: SAP | X35: 유지 | AD35: PP | AE35: PPI2018 SP-20.공장달력 인터페이스 | AF35: 공장달력 인터페이스 누락되어 추가 | AG35: 유지 | AH35: 1
A36: 보류 | B36: =+B35+1 -> 34 | C36: CDP | D36: TBD | F36: INBOUND | G36: DP-50 | H36: 거래처 협업 유통사 판매 재고 | I36: DP | J36: A | K36: 신규 | L36: Y | N36: ALIFCI_PRTN_DSTR_INVN | O36: ALCDCA_PRTN_DSTR_INVN | P36: SP_STGCA_PRTN_DSTR_INVN | Q36: 글루 사용 I/F | R36: 20251020추가 | V36: DP | W36: CDP | X36: 신규 | AC36: 재고, 판매 | AD36: CDP | AE36: 신규 | AF36: 신규 (거래처 협업 유통사 데이터, 84P) 글루 I/F만 허용 | AG36: 신규 | AH36: 5
A37: 보류 | B37: =+B36+1 -> 35 | C37: CDP | D37: TBD | F37: INBOUND | G37: DP-51 | H37: 거래처 협업 유통사 판매 재고(월) | I37: DP | J37: A | K37: 신규 | L37: Y | N37: ALIFCI_PRTN_DSTR_MTH_INVN | O37: ALCDCA_PRTN_DSTR_MTH_INVN | P37: SP_STGCA_PRTN_DSTR_MTH_INVN | Q37: 글루 사용 I/F | R37: 20251020추가 | V37: DP | W37: CDP | X37: 신규 | AC37: 재고, 판매 (월) | AD37: CDP | AE37: 신규 | AF37: 신규 (거래처 협업 유통사 데이터, 84P) 글루 I/F만 허용 | AG37: 신규 | AH37: 5
A38: 보류 | B38: =+B37+1 -> 36 | C38: CDP | D38: TBD | F38: INBOUND | G38: SP-42 | H38: 재고 Aging 상태 | I38: SP | J38: A | K38: 신규 | L38: Y | N38: ALIFCI_INVN_AG_ST | O38: ALCDCA_INVN_AG_ST | P38: SP_STGCA_INVN_AG_ST | Q38: 글루 사용 I/F | R38: 20251020추가 | V38: SP | W38: CDP | X38: 신규 | AC38: SAP, EWM, 아폴로, 3PL 데이터를 CDP에서 통합하여 연계 | AD38: CDP | AE38: 신규 | AF38: 신규 (재고 Aging, 52P) 글루 I/F만 허용 | AG38: 신규 | AH38: 5
A39: 보류 | B39: =+B38+1 -> 37 | C39: CDP | D39: TBD | F39: INBOUND | G39: DP-52 | H39: 엔진상품 리스트 | I39: SP | J39: M | K39: 신규 | L39: Y | N39: ALIFCI_ENGN_PRD | O39: ALCDCM_ENGN_PRD | P39: SP_STGCM_ENGN_PRD | Q39: 글루 사용 I/F | R39: 20251020추가 | V39: SP | W39: CDP | X39: 신규 | AD39: CDP | AE39: 신규 | AF39: 글루 I/F만 허용 | AG39: 신규 | AH39: 5
B40: =+B39+1 -> 38 | C40: BW | D40: BII0237 | E40: BII0237 | F40: INBOUND | G40: DP-42-1 | H40: DP-42-1. 자재정보추가_BW | I40: 공통 | J40: M | K40: 신규 | L40: Y | N40: ALIFCI_MTRL_XTRA_ATTR1 | O40: ALCDCM_MTRL_MSTR(업데이트 Only) | P40: SP_STGCM_MTRL_MSTR_XTRA1 | R40: 20251020추가 | V40: 공통 | W40: BW | X40: 신규 | Z40: File | AD40: BW | AE40: 신규 | AG40: 신규
B41: =+B40+1 -> 39 | C41: BW | D41: BII0238 | E41: BII0238 | F41: INBOUND | G41: DP-42-2 | H41: DP-42-2. 자재정보추가_BW | I41: 공통 | J41: M | K41: 신규 | L41: Y | N41: ALIFCI_MTRL_XTRA_ATTR2 | O41: ALCDCM_MTRL_MSTR_CP(업데이트 Only) | P41: SP_STGCM_MTRL_MSTR_XTRA2 | R41: 20251020추가 | V41: 공통 | W41: BW | X41: 신규 | Z41: File | AD41: BW | AE41: 신규
...

Sheet 개요
B2: I/F 연관시스템 | C2: 시스템 관리팀 | D2: 시스템 담당자
B3: SAP
B4: NPD
B5: AP-ON
B6: BW
B7: 구매포털
B8: IAM
B9: MES
B10: CDP
B12: Inbound Interface Data 처리 Logic
B13: 1. Purge Old i/f data(인터페이스 항목 별로 보존기간이 지난 data이고 i/f data 상태가 처리 또는 에러상태)
B14: 2. Backup (신규 인터페이스 데이터를 일자별로 백업테이블로 저장)
B15: 3. 신규 i/f Group id 채번
... B141: CP-132.판매계획 프로모션 정보

Sheet Inbound
B2: No | C2: Interface ID | D2: In/Out | E2: 항목 | F2: Aplan 구분 | G2: Source System | H2: 작업유형 | I2: Delta/Full Data | J2: API/File | K2: 비고 | L2: Batch Cycle | M2: Batch Cycle Detail | N2: Source/Target Table Name
B3: 1 | C3: TBD | D3: IN | E3: 조직도 | F3: 공통 | G3: SAP | H3: 유지 | I3: Delta | J3: API | L3: W | M3: Random | N3: ZSD_SEND_ORG_01
B4: 2 | C4: TBD | D4: IN | E4: 자재마스터(영업조직:CP) | F4: 공통 | G4: SAP | H4: 유지 | I4: Delta | J4: API | K4: 영업조직/Item 별 속성정보 | L4: W,D | M4: 10Min | N4: ZSD_SEND_MATERIAL_01
B5: 3 | C5: TBD | D5: IN | E5: 자재 마스터(플랜트:SP) | F5: 공통 | G5: SAP | H5: 유지 | I5: Delta | J5: API | L5: W,D | M5: 15Min | N5: ZPP_IF_MAT_SEND_SP
B6: 4 | C6: TBD | D6: IN | E6: 자재 단가 | F6: 공통 | G6: SAP | H6: 유지 | I6: Delta | J6: API | K6: 판가 정보 | L6: W,D | M6: 10Min | N6: ZSD_SEND_CHANNEL_PRICE
B7: 5 | C7: TBD | D7: IN | E7: NPD 자재 목록 | F7: 공통 | G7: NPD | H7: 유지 | I7: Full | J7: API | K7: 현행화 주기 나 대상 검토 필요, 현재 업데이트가 되고 있지 않음 | L7: W,D | M7: Daily | N7: ZPL_IF_DEVHEAD_SINGLE
B8: 6 | C8: TBD | D8: IN | E8: 제품 허가 정보 | F8: 공통 | G8: SAP | H8: 유지 | I8: Full | J8: API | K8: BOD 및 SKU IN/OUT 에서 사용함 | L8: W,D | M8: Daily | N8: ZSD_SEND_CONFIRM_MAT_O9
B9: 7 | C9: TBD | D9: IN | E9: 단종 품의 완료 상태 | F9: 공통 | G9: AP-ON | H9: 신규 | I9: Real Time | J9: API | K9: AP-ON I/F (압축 품의 정보 전송 필요 BI -> AP-ON) (변경BI 압축 품의 진행 여부 확인 필요) | L9: 15Min | M9: Random | N9: TBD
B10: 8 | C10: TBD | D10: IN | E10: SKU 현황 | F10: 공통 | G10: BW | H10: 유지 | I10: Full | J10: File | L10: W,D | M10: Daily | N10: ZBI_SEND_FILE_TO_O9
B11: 9 | C11: TBD | D11: IN | E11: SKU In 일정 | F11: 공통 | G11: NPD | H11: 유지 | I11: Full | J11: API | L11: W,D | M11: Daily | N11: ZPL_IF_MT_SINGLE
B12: 10 | C12: TBD | D12: IN | E12: UOM Conversion Rule | F12: 공통 | G12: SAP | H12: 유지 | I12: Full
B13: 11 | C13: TBD | D13: IN | E13: 자재마스터 원가정보 | F13: 공통 | G13: SAP | H13: 유지 | I13: Delta | J13: API | K13: 해외 정보 확인 필요 | L13: D | M13: Daily | N13: ZPP_IF_STD_PRICE_SEND_SP
B14: 12 | C14: TBD | D14: IN | E14: 재고 | F14: 공통 | G14: BW | H14: 유지 | I14: Full | J14: File | L14: D | M14: Daily | N14: ZBI_SEND_FILE_TO_O9
B15: 13 | C15: TBD | D15: IN | E15: Lot ID별 재고정보 | F15: 공통 | G15: TBD | H15: 신규 | I15: Full | J15: File | K15: 재고(계획용) | L15: D | M15: Daily | N15: TBD
B16: 14 | C16: TBD | D16: IN | E16: 플랜트 저장위치 매핑 마스터 | F16: SP | G16: SAP | H16: 신규 | I16: Delta | J16: API | K16: BIM Inbound 삭제 , BIM Outbound 추가 | L16: W | M16: Daily | N16: TBD
B17: 15 | C17: TBD | D17: IN | E17: 거래처마스터 | F17: DP | G17: SAP | H17: 유지 | I17: Delta | J17: API | L17: W | M17: 15Min | N17: ZSD_SEND_CUSTOMER_01
B18: 16 | C18: TBD | D18: IN | E18: 채널- GPS 목표채널 Mapping 정보 | F18: DP | G18: BW | H18: 신규 | I18: Delta | J18: API | K18: 그룹거래처 채널- GPS 목표채널 Mapping 정보 BW 에서 신규 I/F 필요 | L18: W | M18: 15Min | N18: TBD
B19: 17 | C19: TBD | D19: IN | E19: 주문 실적/결품 수량 | F19: DP | G19: BW | H19: 수정 | I19: Full | J19: File | K19: Layout 변경(PG → Sold-To-Party 로 변경 | L19: W,D | M19: Daily | N19: ZBI_SEND_FILE_TO_O9
B20: 18 | C20: TBD | D20: IN | E20: 판매 실적 | F20: DP | G20: BW | H20: 수정 | I20: Full | J20: File | K20: Layout 변경(PG → Sold-To-Party 로 변경 | L20: W,D | M20: Daily | N20: ZBI_SEND_FILE_TO_O9
B21: 19 | C21: TBD | D21: IN | E21: SKU 목표 | F21: DP | G21: BW | H21: 유지 | I21: Full | J21: File | L21: W,D | M21: Daily | N21: ZBI_SEND_FILE_TO_O9
B22: 20 | C22: TBD | D22: IN | E22: 기준환율 | F22: DP | G22: BW | H22: 유지 | I22: Full | J22: File | K22: 유지(값의 정합성 확인 필요) 영업 조직별 기준환율이 I/F 되어야 함 | L22: W,D | M22: Daily | N22: ZBI_SEND_FILE_TO_O9
B23: 21 | C23: TBD | D23: IN | E23: 수출 진행 모니터링 | F23: DP | G23: SAP | H23: 유지 | I23: Full | J23: API | L23: W,D | M23: Daily | N23: ZSD_SEND_EXPORT_O9
B24: 22 | C24: TBD | D24: IN | E24: 거래처 재고 | F24: DP | G24: BW | H24: 유지 | I24: Full | J24: File | L24: W,D | M24: Daily | N24: ZBI_SEND_FILE_TO_O9
B25: 23 | C25: TBD | D25: IN | E25: 기타 수요(잡출) | F25: DP | G25: BW | H25: 수정 | I25: Full | J25: File | K25: Layout 변경(PG → Sold-To-Party 로 변경 | L25: Weekly,Daily | M25: Daily | N25: ZBI_SEND_FILE_TO_O9
B26: 24 | C26: TBD | D26: IN | E26: BOM | F26: SP | G26: SAP | H26: 유지 | I26: Delta | J26: API | L26: D | M26: Daily | N26: ZPP_IF_BOM_SEND_SP
B27: 25 | C27: TBD | D27: IN | E27: BOM On-demand | F27: SP | G27: SAP | H27: 유지 | I27: - | J27: API | L27: 15Min | M27: On-Demand | N27: ZPP_IF_SP_GET_BOM
B28: 26 | C28: TBD | D28: IN | E28: 작업장 마스터 | F28: SP | G28: SAP | H28: 유지 | I28: Delta | J28: API | K28: (작업장 기준 Grouping 해서 Resource 로 정의 | L28: W | M28: Random | N28: ZPP_IF_WORKCENTER_SEND_SP
B29: 27 | C29: TBD | D29: IN | E29: ROS | F29: SP | G29: SAP | H29: 신규 | I29: Full | J29: API | K29: 해외사업장 확장으로 인해서 원천을 SAP 로 변경, MES 한국 Plant만 존재함 | L29: 15Min | M29: 목(Thu)/토(Sat) | N29: MWRKTI_ROS_PACK_PRFR_SND
B30: 28 | C30: TBD | D30: IN | E30: ROS On-demand | F30: SP | G30: SAP | H30: 신규 | I30: - | J30: API | K30: 해외사업장 확장으로 인해서 원천을 SAP 로 변경, MES 한국 Plant만 존재함 | L30: - | M30: On-Demand | N30: MWRKTI_ROS_PACK_PRFR_SND
B31: 29 | C31: TBD | D31: IN | E31: 생산 오더 | F31: SP | G31: SAP | H31: 유지 | I31: Delta | J31: API | K31: 국내 포함 전체(해외)Plant 반영 필요 | L31: W,D | M31: Daily | N31: ZPP_IF_PROD_ORDER_SEND_SP
B32: 30 | C32: TBD | D32: IN | E32: 생산 오더 On-demand | F32: SP | G32: SAP | H32: 유지 | I32: - | J32: API | L32: 15Min | M32: On-Demand | N32: ZPP_IF_SP_GET_PROD_ORDER
B33: 31 | C33: TBD | D33: IN | E33: 구매오더 | F33: SP | G33: SAP | H33: 유지 | I33: Delta | J33: API | K33: ODM 포함 전체 구매오더로 반영되어야 하고 확인 필요 | L33: W,D | M33: Daily | N33: ZPP_IF_PURCH_ORDER_SEND_SP
B34: 32 | C34: TBD | D34: IN | E34: 구매정보(ODM 외주 원부자재) | F34: SP | G34: SAP | H34: 유지 | I34: Delta | J34: API | K34: ODM Network 구성 및 포장재 구매처 정의 (Category 컬럼-> 구매 또는 외주가공 정의 가능) | L34: W,D | M34: Daily | N34: ZPP_IF_INFOREC_SEND_SP
B35: 33 | C35: TBD | D35: IN | E35: 협력사 마스터 | F35: SP | G35: SAP | H35: 유지 | I35: Delta | J35: API | L35: W | M35: Daily | N35: ZPP_IF_VENDOR_SEND_SP
B36: 34 | C36: TBD | D36: IN | E36: 가용화 입고 실적 | F36: SP | G36: SAP | H36: 유지 | I36: Delta | J36: API | K36: 엔진 Input은 아니나 활용 측면에서 검토 필요 | L36: 2/Day | M36: 2/day( 11AM , 03PM) | N36: ZPP_IF_AVAIL_STOCK_SEND_SP
B37: 35 | C37: TBD | D37: IN | E37: 협력사 원부자재 재고 | F37: SP | G37: 구매포털 | H37: 유지 | I37: Full | J37: API | L37: W,D | M37: Daily | N37: -
B38: 36 | C38: TBD | D38: IN | E38: SOP 잔량 정보 | F38: SP | G38: SAP | H38: 유지 | I38: Full | J38: API | K38: 선적잔량 | L38: W,D | M38: Sunday | N38: ZSC_PIR_O9_SAP_002
B39: 37 | C39: TBD | D39: IN | E39: 반제품 포장재 MD04 재고 | F39: SP | G39: SAP | H39: 유지 | I39: Full | J39: API | K39: 반제품 재고 수량 + QA 수량 | L39: 2/Day | M39: Daily | N39: ZPP_IF_MD04STOCK_SEND_SP
B40: 38 | C40: TBD | D40: IN | E40: Role 권한 승인 정보 | F40: System | G40: IAM | H40: 유지 | I40: - | J40: API | L40: 2/Day | M40: 11:30:00 AM / 04:30 PM | N40: EX_IF_ROLE
B41: 39 | C41: TBD | D41: IN | E41: 계정 승인 정보 | F41: System | G41: IAM | H41: 유지 | I41: Delta | J41: API | L41: 2/Day | M41: 11:30:00 AM / 04:30 PM | N41: EX_IF_RES_USER
...

Sheet 조직도
A1: Top
B2: 매핑정의서 - 조직도 | J2: Source System | K2: SAP | O2: 문서작성일 | P2: 2025.09.25
J3: Target System | K3: APLAN | O3: 버전 | P3: 0.1
B4: 매핑정의
B5: Source Table : ? | I5: Target Table : ALIFCI_OGCH_MSTR | R5: Set Value | S5: 변환규칙 | Z5: CDP 자재 마스터 테이블 명세서 (D_PRD_MSTR)
B6: RFC | C6: ZSD_SEND_ORG_BM_01 | I6: Web SVC | J6: PreProd : https://myamorepacificpreprod.o9solutions.com/ Prod : https://myamorepacific.o9solutions.com/
B7: SEQ | C7: Field | D7: PK | E7: Type | F7: Size | G7: Desc | H7: Desc(ENG) | I7: SEQ | J7: Field | K7: PK | L7: Type | M7: Size | N7: Desc | O7: Desc(ENG) | P7: Req No | Q7: Res No | Z7: 컬럼명 | AA7: 데이터타입 | AB7: 한글명 | AC7: 영문명
B8: 1 | C8: I_LEGACY | E8: CHAR | F8: 5 | G8: LEGACY SYSTEM 명 | H8: Legacy System Name | I8: 1 | Z8: PRD_CD | AA8: VARCHAR(12) | AB8: 상품코드 | AC8: Product Code.
B9: 2 | C9: BUKRS | D9: Y | E9: CHAR | F9: 4 | G9: 회사코드 | H9: Company code | I9: 2 | J9: Company | L9: NVARCHAR2 | M9: 1000 | N9: 회사코드 | O9: Company code | Z9: PRD_NM | AA9: VARCHAR(100) | AB9: 상품명 | AC9: Product Name.
B10: 3 | C10: VKORG | D10: Y | E10: CHAR | F10: 4 | G10: 영업조직 | H10: Sales organization | I10: 3 | J10: SalesOrg | L10: NVARCHAR2 | M10: 1000 | N10: 영업조직 | O10: Sales organization | Z10: PRD_ENGL_NM | AA10: VARCHAR(200) | AB10: 상품영어명 | AC10: Product English Name.
B11: 4 | C11: SUBSC | D11: Y | E11: CHAR | F11: 4 | G11: 하위영업경로 | H11: Sub -business path | I11: 4 | J11: Channel | L11: NVARCHAR2 | M11: 1000 | N11: 하위영업경로 | O11: Sub -business path | Z11: ENGL_PRD_NM | AA11: VARCHAR(100) | AB11: 영어상품명(비표준) | AC11: English Product Name (Non-Standard).
B12: 5 | C12: LAND1 | E12: CHAR | F12: 3 | G12: 국가 | H12: nation | I12: 5 | J12: Country | L12: NVARCHAR2 | M12: 1000 | N12: 국가 | O12: nation | Z12: BRND_CD | AA12: VARCHAR(5) | AB12: 브랜드코드 | AC12: Brand Code.
B13: 6 | C13: BUSUN | D13: Y | E13: CHAR | F13: 4 | G13: BU | H13: BU | I13: 6 | J13: BU | L13: NVARCHAR2 | M13: 1000 | N13: BU(사업부) | O13: BU | Z13: BRND_DTL_CD | AA13: VARCHAR(6) | AB13: 브랜드상세코드 | AC13: Brand Detail Code.
B14: 7 | C14: ZMODE | E14: CHAR | F14: 1 | G14: 'I' (Insert) , 'U'(Update), 'D'(Delete) | H14: 'I' (INSERT), 'U' (update), 'D' (Delete) | I14: 7 | J14: CUD | L14: NVARCHAR2 | M14: 1000 | N14: 'I' (Insert) , 'U'(Update), 'D'(Delete) | O14: 'I' (INSERT), 'U' (update), 'D' (Delete) | Z14: RPRS_PRD_CD | AA14: VARCHAR(12) | AB14: 대표상품코드 | AC14: Representative Product Code.
B15: 8 | C15: TFLG | E15: CHAR | F15: 1 | G15: 이관 Flag | H15: Transfer flag | I15: 8 | J15: TransFlag | L15: NVARCHAR2 | M15: 1000 | N15: 이관 Flag | O15: Transfer flag | Z15: RPRS_PRD_NM | AA15: VARCHAR(100) | AB15: 대표상품명 | AC15: Product Name.
B16: 9 | C16: .INCLUDE | E16: STRU | F16: 0 | G16: Cr/Ch log | H16: Cr/ch log | I16: 9 | Z16: RPRS_PRD_ENGL_NM | AA16: VARCHAR(100) | AB16: 대표상품영어명 | AC16: Representative Product English Name.
B17: 10 | C17: ERDAT | E17: DATS | F17: 8 | G17: 레코드 생성일 | H17: Record creation date | I17: 10 | J17: IF_DATE | L17: DATE | N17: 인터페이스 일자 | O17: Interface date | Z17: RPLC_PRD_CD | AA17: VARCHAR(12) | AB17: 대체상품코드 | AC17: Alternative Product Code.
B18: 11 | C18: ERZET | E18: TIMS | F18: 6 | G18: 입력 시간 | H18: Input time | I18: 11 | J18: IF_STATUS | L18: VARCHAR2 | M18: 30 | N18: 인터페이스 처리 상태 | O18: Interface Status | Z18: PRD_MKT_CAT_CD | AA18: VARCHAR(2) | AB18: 상품마케팅분류코드 | AC18: Product Marketing Classification Code.
B19: 12 | C19: ERNAM | E19: CHAR | F19: 12 | G19: 오브젝트 생성자 이름 | H19: Object constructor name | I19: 12 | J19: IF_PROCESS_DATE | L19: DATE | N19: 인터페이스 처리 일자 | O19: Interface Process date | Z19: SET_PRD_YN | AA19: VARCHAR(1) | AB19: 세트상품여부 | AC19: Set product or not.
B20: 13 | C20: AEDAT | E20: DATS | F20: 8 | G20: 변경일 | H20: Change date | I20: 13 | J20: IF_GRP_ID | L20: NUMBER | N20: 인터페이스 그룹 id(처리 시) | O20: Interface group id | Z20: SET_DSMN_YN | AA20: VARCHAR(1) | AB20: 세트해체여부 | AC20: Set disassembly.
B21: 14 | C21: AEZET | E21: TIMS | F21: 6 | G21: 최종변경시간 | H21: Final change time | I21: 14 | Z21: CNSM_UTPR_AMT | AA21: NUMBER(20,3) | AB21: 소비자단가금액 | AC21: Consumer Unit Price.
B22: 15 | C22: AENAM | E22: CHAR | F22: 12 | G22: 오브젝트 변경자 이름 | H22: Object Changer Name | I22: 15 | Z22: PRD_CPT | AA22: NUMBER(38,0) | AB22: 상품용량 | AC22: Product Capacity.
B23: 16 | I23: 16 | Z23: PRD_CPT_UNIT_CD | AA23: VARCHAR(3) | AB23: 상품용량단위코드 | AC23: Product Unit Code.
B24: 17 | I24: 17 | Z24: PRD_USE_CD | AA24: VARCHAR(3) | AB24: 상품용도코드 | AC24: Product Use Code.
B25: 18 | I25: 18 | Z25: PRD_CAT_CD | AA25: VARCHAR(10) | AB25: 상품분류코드 | AC25: Product Classification Code.
B26: 19 | I26: 19 | Z26: MAIN_FUNC_CD | AA26: VARCHAR(4) | AB26: 주요기능코드 | AC26: Main Function Code.
B27: 20 | I27: 20 | Z27: USER_TP_CD | AA27: VARCHAR(1) | AB27: 사용자유형코드 | AC27: User Type Code.
B28: 21 | I28: 21 | Z28: FRSH_CSMT_YN | AA28: VARCHAR(1) | AB28: 신선화장품여부 | AC28: Fresh Cosmetics.
B29: 22 | I29: 22 | Z29: PRD_CL_CD | AA29: VARCHAR(2) | AB29: 상품구분코드 | AC29: Product Classification Code.
B30: 23 | I30: 23 | Z30: SLS_TP_CD | AA30: VARCHAR(3) | AB30: 영업유형코드 | AC30: Sales Type Code.
B31: 24 | I31: 24 | Z31: SAP_PRD_LN_CD | AA31: VARCHAR(4) | AB31: SAP상품라인코드 | AC31: SAP Product Line Code.
B32: 25 | I32: 25 | Z32: PRD_CLR_CD | AA32: VARCHAR(4) | AB32: 상품색상코드 | AC32: Product Color Code.
B33: 26 | I33: 26 | Z33: NEW_PRD_CL_CD | AA33: VARCHAR(3) | AB33: 신상품구분코드 | AC33: New Product Code.
B34: 27 | I34: 27 | Z34: STRO_PRD_YN | AA34: VARCHAR(1) | AB34: 강한상품여부 | AC34: Strong product or not.
... B38: 31 | I38: 31 | Z38: BRND_LN_CD | AA38: VARCHAR(4) | AB38: 브랜드라인코드 | AC38: Brand Line Code.
Z39: MFG_PLNT_CD | AA39: VARCHAR(4) | AB39: 생산플랜트코드 | AC39: Production Plant Code.
Z40: NITM_APLY_YN | AA40: VARCHAR(1) | AB40: 품목수적용여부 | AC40: Item Application.
B41: 변환규칙정의 | Z41: FST_MFG_DT | AA41: VARCHAR(10) | AB41: 최초생산일자 | AC41: Initial Production Date.
B42: 변환규칙 | D42: 내용 | Z42: LST_MFG_DT | AA42: VARCHAR(10) | AB42: 최종생산일자 | AC42: Final production date.
B43: R1 | Z43: PRD_BRCD_CD | AA43: VARCHAR(15) | AB43: 상품바코드코드 | AC43: Product barcode code.
...

Sheet 자재마스터(영업조직)
A1: Top
B2: 매핑정의서 - 자재마스터(Sales ORG.) Item Master CP | J2: Source System | K2: SAP | O2: 문서작성일 | P2: 2025.09.25
J3: Target System | K3: APLAN | O3: 버전 | P3: 0.1
B4: 매핑정의
B5: Source Table : ? | I5: Target Table : ALIFCI_MTRL_MSTR_CP | R5: Set Value | S5: 변환 규칙
B6: RFC | C6: ZSD_SEND_MATERIAL_01 | I6: Web SVC | J6: PreProd : https://myamorepacificpreprod.o9solutions.com/ Prod : https://myamorepacific.o9solutions.com/
B7: SEQ | C7: Field | D7: PK | E7: Type | F7: Size | G7: Desc | H7: Desc(ENG) | I7: SEQ | J7: Field | K7: PK | L7: Type | M7: Size | N7: Desc | O7: Desc(ENG) | P7: Req No | Q7: Res No
B8: 1 | C8: MATNR | D8: Y | E8: CHAR | F8: 18 | G8: 자재코드 | H8: Material code | I8: 1 | J8: Item | K8: Y | L8: nvarchar2 | M8: 1000 | N8: 자재코드 | O8: Material code
B9: 2 | C9: VKORG | D9: Y | E9: CHAR | F9: 4 | G9: 판매조직 | H9: Sales organization | I9: 2 | J9: SalesOrg | K9: Y | L9: nvarchar2 | M9: 1000 | N9: 판매조직 | O9: Sales organization
B10: 3 | C10: MAKTX_KO | E10: CHAR | F10: 40 | G10: 자재내역(KO) | H10: Material details (KO) | I10: 3 | J10: ItemDescKR | L10: nvarchar2 | M10: 1000 | N10: 자재내역(KO) | O10: Material details (KO) | T10: 자재공통칼럼
B11: 4 | C11: MTART | E11: CHAR | F11: 4 | G11: 자재유형 | H11: Material | I11: 4 | J11: ItemType | L11: nvarchar2 | M11: 1000 | N11: 자재유형 | O11: Material | T11: 자재공통칼럼
B12: 5 | C12: BISMT | E12: CHAR | F12: 18 | G12: 이전상품코드 | H12: Previous product code | I12: 5 | J12: OldItem | L12: nvarchar2 | M12: 1000 | N12: 이전상품코드 | O12: Previous product code
B13: 6 | C13: LABOR | E13: CHAR | F13: 3 | G13: 상품개발담당자 | H13: Product operation manager | I13: 6 | J13: ProdOpPerson | L13: nvarchar2 | M13: 1000 | N13: 상품개발담당자 | O13: Product operation manager | T13: 자재공통칼럼
B14: 7 | C14: BRAND | E14: CHAR | F14: 9 | G14: 브랜드코드 | H14: Brand code | I14: 7 | J14: Brand | L14: nvarchar2 | M14: 1000 | N14: 브랜드코드 | O14: Brand code | T14: 자재공통칼럼
B15: 8 | C15: BCTXT_KO | E15: CHAR | F15: 20 | G15: 브랜드명(KO) | H15: Brand name (KO) | I15: 8 | J15: BrandDescKR | L15: nvarchar2 | M15: 1000 | N15: 브랜드명(KO) | O15: Brand name (KO) | T15: 자재공통칼럼
B16: 9 | C16: MEINS | E16: CHAR | F16: 3 | G16: 기본단위 | H16: Basic unit | I16: 9 | J16: UOM | L16: nvarchar2 | M16: 1000 | N16: 기본단위 | O16: Basic unit | T16: 자재공통칼럼
B17: 10 | C17: DISPO | E17: CHAR | F17: 3 | G17: MRP관리자 | H17: MRP manager | I17: 10 | J17: MRPPerson | L17: nvarchar2 | M17: 1000 | N17: MRP관리자 | O17: MRP manager
B18: 11 | C18: MVGR1 | E18: CHAR | F18: 3 | G18: 제품용도 | H18: Product use | I18: 11 | J18: MVGR1 | L18: nvarchar2 | M18: 1000 | N18: 제품용도 | O18: Product use
B19: 12 | C19: MVGR2 | E19: CHAR | F19: 3 | G19: 제품등급 | H19: Product grade | I19: 12 | J19: MVGR2 | L19: nvarchar2 | M19: 1000 | N19: 제품등급 | O19: Product grade
B20: 13 | C20: MVGR4 | E20: CHAR | F20: 3 | G20: 자재클래스1 | H20: Material Class 1 | I20: 13 | J20: ItemClass1 | L20: nvarchar2 | M20: 1000 | N20: 자재클래스1 | O20: Material Class 1 | T20: 자재공통칼럼
B21: 14 | C21: MVGR5 | E21: CHAR | F21: 3 | G21: 자재클래스2 | H21: Material Class 2 | I21: 14 | J21: ItemClass2 | L21: nvarchar2 | M21: 1000 | N21: 자재클래스2 | O21: Material Class 2 | T21: 자재공통칼럼
B22: 15 | C22: PRODH | E22: CHAR | F22: 18 | G22: 제품계층구조 | H22: Product hierarchy | I22: 15 | J22: ProdHrcy | L22: nvarchar2 | M22: 1000 | N22: 제품계층구조 | O22: Product hierarchy | T22: 자재공통칼럼
B23: 16 | C23: MATNR2 | E23: CHAR | F23: 18 | G23: 대체자재 | H23: Alternative materials | I23: 16 | J23: ReplaceItem | L23: nvarchar2 | M23: 1000 | N23: 대체자재 | O23: Alternative materials
B24: 17 | C24: ADNEW | E24: CHAR | F24: 3 | G24: NEW/AD | H24: New/AD | I24: 17 | J24: ADNEW | L24: nvarchar2 | M24: 1000 | N24: NEW/AD | O24: New/AD
B25: 18 | C25: SETID | E25: CHAR | F25: 3 | G25: SET구분 | H25: SET classification | I25: 18 | J25: SETID | L25: nvarchar2 | M25: 1000 | N25: SET구분 | O25: SET classification
B26: 19 | C26: MATOP | E26: CHAR | F26: 3 | G26: 상품운영담당 | H26: Product operation manager | I26: 19 | J26: ProdOp | L26: nvarchar2 | M26: 1000 | N26: 상품운영담당 | O26: Product operation manager
B27: 20 | C27: SETDI | E27: CHAR | F27: 1 | G27: 세트해체여부 | H27: Whether to dismantle the set | I27: 20 | J27: SETDI | L27: nvarchar2 | M27: 1000 | N27: 세트해체여부 | O27: Whether to dismantle the set
B28: 21 | C28: MANFT | E28: CHAR | F28: 4 | G28: 제조장 | H28: Manufacture | I28: 21 | J28: Plant | L28: nvarchar2 | M28: 1000 | N28: 제조장 | O28: Manufacture
B29: 22 | C29: LPRDD | E29: CHAR | F29: 8 | G29: 최종생산일 | H29: Final production date | I29: 22 | J29: LastProdDate | L29: nvarchar2 | M29: 1000 | N29: 최종생산일 | O29: Final production date
B30: 23 | C30: FPRDD | E30: CHAR | F30: 8 | G30: 최초생산일 | H30: Initial production date | I30: 23 | J30: FirstProdDate | L30: nvarchar2 | M30: 1000 | N30: 최초생산일 | O30: Initial production date
B31: 24 | C31: MAKTX_EN | E31: CHAR | F31: 40 | G31: 자재내역(EN) | H31: Material details (EN) | I31: 24 | J31: ItemDescEN | L31: nvarchar2 | M31: 1000 | N31: 자재내역(EN) | O31: Material details (EN) | T31: 자재공통칼럼
B32: 25 | C32: MAKTX_ZH | E32: CHAR | F32: 40 | G32: 자재내역(ZH) | H32: Material details (ZH) | I32: 25 | J32: ItemDescZH | L32: nvarchar2 | M32: 1000 | N32: 자재내역(ZH) | O32: Material details (ZH) | T32: 자재공통칼럼
B33: 26 | C33: BCTXT_EN | E33: CHAR | F33: 20 | G33: 브랜드명(EN) | H33: Brand name (EN) | I33: 26 | J33: BrandDescEN | L33: nvarchar2 | M33: 1000 | N33: 브랜드명(EN) | O33: Brand name (EN) | T33: 자재공통칼럼
B34: 27 | C34: BCTXT_ZH | E34: CHAR | F34: 20 | G34: 브랜드명(ZH) | H34: Brand name (ZH) | I34: 27 | J34: BrandDescZH | L34: nvarchar2 | M34: 1000 | N34: 브랜드명(ZH) | O34: Brand name (ZH) | T34: 자재공통칼럼
B35: 28 | C35: MANFT2 | E35: CHAR | F35: 10 | G35: 제조장2 | H35: Manufacturer 2 | I35: 28 | J35: SCMU | L35: nvarchar2 | M35: 1000 | N35: 제조장2 | O35: Manufacturer 2
B36: 29 | C36: SETYN | E36: CHAR | F36: 1 | G36: SET 여부(Y/N) | H36: Whether set (Y/N) | I36: 29 | J36: SetYN | L36: nvarchar2 | M36: 1000 | N36: SET 여부(Y/N) | O36: Whether set (Y/N) | T36: 자재공통칼럼
B37: 30 | C37: MATKL | E37: CHAR | F37: 9 | G37: 자재그룹 | H37: Material group | I37: 30 | J37: ItemGroup | L37: nvarchar2 | M37: 1000 | N37: 자재그룹 | O37: Material group | T37: 자재공통칼럼
B38: 31 | C38: ZZBRANG | E38: CHAR | F38: 10 | G38: 브랜드그룹 | H38: Brand group | I38: 31 | J38: BrandGroup | L38: nvarchar2 | M38: 1000 | N38: 브랜드그룹 | O38: Brand group | T38: 자재공통칼럼
B39: 32 | C39: ZZRPPRD | E39: CHAR | G39: 대표상품 | I39: 32 | J39: Head_PRDT | L39: nvarchar2 | M39: 1000 | N39: 대표상품 | T39: 신규추가.25.09.25 | U39: 자재공통칼럼
B40: 33 | C40: ZZSCGRP | E40: CHAR | G40: 소싱그룹 | I40: 33 | J40: SRC_GRP | L40: nvarchar2 | M40: 1000 | N40: 소싱그룹 | T40: 신규추가.25.09.25
...

Sheet 자재마스터(플랜트)
A1: Top
B2: 매핑정의서 - 자재마스터(Plant) Item Master SP | J2: Source System | K2: SAP | O2: 문서작성일 | P2: 2025.09.25
J3: Target System | K3: APLAN | O3: 버전 | P3: 0.1
B4: 매핑정의
B5: Source Table : ? | I5: Target Table : ALIFCI_MTRL_MSTR_CP | R5: Set Value | S5: 변환 규칙 | Z5: CDP 자재 마스터 테이블 명세서 (D_PRD_MSTR)
B6: RFC | C6: ZPP_IF_MAT_SEND_BM_SP | I6: Web SVC | J6: PreProd : https://myamorepacificpreprod.o9solutions.com/ Prod : https://myamorepacific.o9solutions.com/
B7: SEQ | C7: Field | D7: PK | E7: Type | F7: Size | G7: Desc | H7: Desc(ENG) | I7: SEQ | J7: Field | K7: PK | L7: Type | M7: Size | N7: Desc | O7: Desc(ENG) | P7: Req No | Q7: Res No | Z7: 컬럼명 | AA7: 데이터타입 | AB7: 한글명 | AC7: 영문명
B8: 1 | C8: MATNR | D8: Y | E8: CHAR | F8: 18 | G8: 자재코드 | H8: Material code | I8: 1 | J8: Item | K8: Y | L8: nvarchar | M8: 1000 | N8: 자재코드 | O8: Material code | Z8: PRD_CD | AA8: VARCHAR(12) | AB8: 상품코드 | AC8: Product Code.
B9: 2 | C9: WERKS | D9: Y | E9: CHAR | F9: 4 | G9: Plant | H9: Plant | I9: 2 | J9: Plant | K9: Y | L9: nvarchar | M9: 1000 | N9: 플랜트 | O9: Plant | Z9: PRD_NM | AA9: VARCHAR(100) | AB9: 상품명 | AC9: Product Name.
B10: 3 | C10: BESKZ | E10: CHAR | F10: 1 | G10: 조달유형 | H10: Procurement | I10: 3 | J10: ProcType | L10: nvarchar | M10: 1000 | N10: 조달유형 | O10: Procurement | Z10: PRD_ENGL_NM | AA10: VARCHAR(200) | AB10: 상품영어명 | AC10: Product English Name.
B11: 4 | C11: SOBSL | E11: CHAR | F11: 2 | G11: 특별조달유형 | H11: Special procurement type | I11: 4 | J11: SpecProcType | L11: nvarchar | M11: 1000 | N11: 특별조달유형 | O11: Special procurement type | Z11: ENGL_PRD_NM | AA11: VARCHAR(100) | AB11: 영어상품명(비표준) | AC11: English Product Name (Non-Standard).
B12: 5 | C12: ODM | E12: CHAR | F12: 1 | G12: ODM/OEM flag | H12: ODM/OEM Flag | I12: 5 | J12: ODM | L12: nvarchar | M12: 1000 | N12: ODM | O12: ODM/OEM Flag | Z12: BRND_CD | AA12: VARCHAR(5) | AB12: 브랜드코드 | AC12: Brand Code.
B13: 6 | C13: PROVG | E13: CHAR | F13: 2 | G13: 주요판매경로 | H13: Main | I13: 6 | J13: ExportFlag | L13: nvarchar | M13: 1000 | N13: 수출 여부 | O13: Main | Z13: BRND_DTL_CD | AA13: VARCHAR(6) | AB13: 브랜드상세코드 | AC13: Brand Detail Code.
B14: 7 | C14: ZZMANFT | E14: CHAR | F14: 4 | G14: 소싱플랜트 | H14: Sourcing plant | I14: 7 | J14: SourcingPlant | L14: nvarchar | M14: 1000 | N14: 소싱플랜트 | O14: Sourcing plant | Z14: RPRS_PRD_CD | AA14: VARCHAR(12) | AB14: 대표상품코드 | AC14: Representative Product Code.
B15: 8 | C15: LGFSB | E15: CHAR | F15: 4 | G15: EP 저장위치 | H15: EP storage location | I15: 8 | J15: ReceivingPlant | L15: nvarchar | M15: 1000 | N15: 입고저장위치 | O15: EP storage location | Z15: RPRS_PRD_NM | AA15: VARCHAR(100) | AB15: 대표상품명 | AC15: Product Name.
B16: 9 | C16: LGPRO | E16: CHAR | F16: 4 | G16: 생산 저장위치 | H16: Production storage location | I16: 9 | J16: ProductionLocation | L16: nvarchar | M16: 1000 | N16: 생산저장위치 | O16: Production storage location | Z16: RPRS_PRD_ENGL_NM | AA16: VARCHAR(100) | AB16: 대표상품영어명 | AC16: Representative Product English Name.
B17: 10 | C17: MEINS | E17: CHAR | F17: 3 | G17: 기본단위 | H17: Basic unit | I17: 10 | J17: UOM | L17: nvarchar | M17: 1000 | N17: UOM | O17: Basic unit | T17: 자재공통칼럼 | Z17: RPLC_PRD_CD | AA17: VARCHAR(12) | AB17: 대체상품코드 | AC17: Alternative Product Code.
B18: 11 | C18: BSTMI | E18: QUAN | F18: 13.3 | G18: Minimum Lot Size | H18: Minimum lot size | I18: 11 | J18: MOQ | L18: nvarchar | M18: 1000 | N18: 최소로트크기 | O18: Minimum lot size | Z18: PRD_MKT_CAT_CD | AA18: VARCHAR(2) | AB18: 상품마케팅분류코드 | AC18: Product Marketing Classification Code.
B19: 12 | C19: EKGRP | E19: CHAR | F19: 3 | G19: Purchasing Group | H19: Purchasing Group | I19: 12 | J19: PurchacingGroup | L19: nvarchar | M19: 1000 | N19: 구매그룹 | O19: Purchasing Group | Z19: SET_PRD_YN | AA19: VARCHAR(1) | AB19: 세트상품여부 | AC19: Set product or not.
B20: 13 | C20: MTART | E20: CHAR | F20: 4 | G20: Material Type | H20: Material type | I20: 13 | J20: ItemType | L20: nvarchar | M20: 1000 | N20: Material Type | O20: Material type | T20: 자재공통칼럼 | Z20: SET_DSMN_YN | AA20: VARCHAR(1) | AB20: 세트해체여부 | AC20: Set disassembly.
B21: 14 | C21: MAKTX | E21: CHAR | F21: 40 | G21: Material Description (Short Text) | H21: Material Description (Short Text) | I21: 14 | J21: ItemDesc | L21: nvarchar | M21: 1000 | N21: Material Description (Short Text) | O21: Material Description (Short Text) | T21: 자재공통칼럼 | Z21: CNSM_UTPR_AMT | AA21: NUMBER(20,3) | AB21: 소비자단가금액 | AC21: Consumer Unit Price.
B22: 15 | C22: MAKTX EN | E22: CHAR | F22: 40 | G22: Material Description (Short Text-EN) | H22: Material Description (Short Text -en) | I22: 15 | J22: ItemDescEN | L22: nvarchar | M22: 1000 | N22: Material Description (Short Text-EN) | O22: Material Description (Short Text -en) | T22: 자재공통칼럼 | Z22: PRD_CPT | AA22: NUMBER(38,0) | AB22: 상품용량 | AC22: Product Capacity.
B23: 16 | C23: MAKTX KO | E23: CHAR | F23: 40 | G23: Material Description (Short Text-KO) | H23: Material Description (Short Text-KO) | I23: 16 | J23: ItemDescKR | L23: nvarchar | M23: 1000 | N23: Material Description (Short Text-KO) | O23: Material Description (Short Text-KO) | T23: 자재공통칼럼 | Z23: PRD_CPT_UNIT_CD | AA23: VARCHAR(3) | AB23: 상품용량단위코드 | AC23: Product Unit Code.
B24: 17 | C24: MAKTX ZH | E24: CHAR | F24: 40 | G24: Material Description (Short Text-ZH) | H24: Material Description (Short Text-ZH) | I24: 17 | J24: ItemDescZH | L24: nvarchar | M24: 1000 | N24: Material Description (Short Text-ZH) | O24: Material Description (Short Text-ZH) | T24: 자재공통칼럼 | Z24: PRD_USE_CD | AA24: VARCHAR(3) | AB24: 상품용도코드 | AC24: Product Use Code.
B25: 18 | C25: ADNEW | E25: CHAR | F25: 3 | G25: AD or New | H25: AD or New | I25: 18 | J25: ADNEW | L25: nvarchar | M25: 1000 | N25: AD or New | O25: AD or New | Z25: PRD_CAT_CD | AA25: VARCHAR(10) | AB25: 상품분류코드 | AC25: Product Classification Code.
B26: 19 | C26: SETID | E26: CHAR | F26: 3 | G26: SET Indicator | H26: Set indicator | I26: 19 | J26: SETID | L26: nvarchar | M26: 1000 | N26: SET Indicator | O26: Set indicator | Z26: MAIN_FUNC_CD | AA26: VARCHAR(4) | AB26: 주요기능코드 | AC26: Main Function Code.
B27: 20 | C27: SETYN | E27: CHAR | F27: 1 | G27: SET (Y/N) | H27: Set (Y/N) | I27: 20 | J27: SetYN | L27: nvarchar | M27: 1000 | N27: SET (Y/N) | O27: Set (Y/N) | T27: 자재공통칼럼 | Z27: USER_TP_CD | AA27: VARCHAR(1) | AB27: 사용자유형코드 | AC27: User Type Code.
B28: 21 | C28: DISPO | E28: CHAR | F28: 3 | G28: MRP Controller (Materials Planner) | H28: MRP Controller (Materials Planner) | I28: 21 | J28: MRPPerson | L28: nvarchar | M28: 1000 | N28: MRP Controller (Materials Planner) | O28: MRP Controller (Materials Planner) | Z28: FRSH_CSMT_YN | AA28: VARCHAR(1) | AB28: 신선화장품여부 | AC28: Fresh Cosmetics.
B29: 22 | C29: LABOR | E29: CHAR | F29: 3 | G29: Laboratory/design office | H29: Laboratory/Design Office | I29: 22 | J29: ProdOpPerson | L29: nvarchar | M29: 1000 | N29: Laboratory/design office | O29: Laboratory/Design Office | Z29: PRD_CL_CD | AA29: VARCHAR(2) | AB29: 상품구분코드 | AC29: Product Classification Code.
B30: 23 | C30: MATKL | E30: CHAR | F30: 9 | G30: Material Group | H30: Material Group | I30: 23 | J30: ItemGroup | L30: nvarchar | M30: 1000 | N30: Material Group | O30: Material Group | T30: 자재공통칼럼 | Z30: SLS_TP_CD | AA30: VARCHAR(3) | AB30: 영업유형코드 | AC30: Sales Type Code.
B31: 24 | C31: BRAND | E31: CHAR | F31: 10 | G31: Brand Code | H31: Brand code | I31: 24 | J31: Brand | L31: nvarchar | M31: 1000 | N31: Brand Code | O31: Brand code | T31: 자재공통칼럼 | Z31: SAP_PRD_LN_CD | AA31: VARCHAR(4) | AB31: SAP상품라인코드 | AC31: SAP Product Line Code.
B32: 25 | C32: BCTXT | E32: CHAR | F32: 40 | G32: Description | H32: Description | I32: 25 | J32: BrandDescKR | L32: nvarchar | M32: 1000 | N32: Description | O32: Description | T32: 자재공통칼럼 | Z32: PRD_CLR_CD | AA32: VARCHAR(4) | AB32: 상품색상코드 | AC32: Product Color Code.
B33: 26 | C33: MVGR1 | E33: CHAR | F33: 3 | G33: Material Usage | H33: Material usage | I33: 26 | J33: MVGR1 | L33: nvarchar | M33: 1000 | N33: Material Usage | O33: Material usage | Z33: NEW_PRD_CL_CD | AA33: VARCHAR(3) | AB33: 신상품구분코드 | AC33: New Product Code.
B34: 27 | C34: MVGR2 | E34: CHAR | F34: 3 | G34: Material Grade | H34: Material Grade | I34: 27 | J34: MVGR2 | L34: nvarchar | M34: 1000 | N34: Material Grade | O34: Material Grade | Z34: STRO_PRD_YN | AA34: VARCHAR(1) | AB34: 강한상품여부 | AC34: Strong product or not.
B35: 28 | C35: PRODH | E35: CHAR | F35: 18 | G35: Product hierarchy | H35: Product Hierarchy | I35: 28 | J35: ProdHrcy | L35: nvarchar | M35: 1000 | N35: Product hierarchy | O35: Product Hierarchy | Z35: INNO_PRD_YN | AA35: VARCHAR(1) | AB35: 혁신상품여부 | AC35: Innovative Product Status.
B36: 29 | C36: BISMT | E36: CHAR | F36: 18 | G36: Old material number | H36: Old Material Number | I36: 29 | J36: OldItem | L36: nvarchar | M36: 1000 | N36: Old material number | O36: Old Material Number | Z36: CUSH_PRD_YN | AA36: VARCHAR(1) | AB36: 쿠션상품여부 | AC36: Cushion product status.
B37: 30 | C37: DISMM | E37: CHAR | F37: 2 | G37: MRP유형 | H37: MRP type | I37: 30 | J37: MRPType | L37: nvarchar | M37: 1000 | N37: MRP유형 | O37: MRP type | Z37: PRD_GRD_CD | AA37: VARCHAR(3) | AB37: 상품등급코드 | AC37: Product Grade Code.
B38: 31 | C38: VKORG | E38: CHAR | F38: 4 | G38: 영업조직 | H38: Sales organization | I38: 31 | J38: SalesOrg | L38: nvarchar | M38: 1000 | N38: 영업조직 | O38: Sales organization | Z38: BRND_LN_CD | AA38: VARCHAR(4) | AB38: 브랜드라인코드 | AC38: Brand Line Code.
B39: 32 | C39: LVORM | E39: CHAR | F39: 1 | G39: 삭제지시자 | H39: Delete Flag | I39: 32 | J39: DeleteFlag | L39: NVARCHAR | M39: 1000 | N39: 삭제지시자 | O39: Delete Flag
B40: 33 | C40: CUD_CI | E40: CHAR | F40: 1 | G40: CUD 구분 | H40: CUD classification | I40: 33 | J40: CUD | L40: NVARCHAR | M40: 1000 | N40: D : 삭제 | O40: CUD classification
...

Sheet 자재단가(판가)
A1: Top
B2: 매핑정의서 - 자재단가(판가) | J2: Source System | K2: SAP | O2: 문서작성일 | P2: 2025.09.25
J3: Target System | K3: APLAN | O3: 버전 | P3: 0.1
B4: 매핑정의
B5: Source Table : ? | I5: Target Table : ? | R5: Set Value | S5: 변환 규칙 | Z5: CDP 자재 마스터 테이블 명세서 (D_PRD_MSTR)
B6: RFC | C6: ZSD_SEND_CHANNEL_PRICE | I6: Web SVC | J6: PreProd : https://myamorepacificpreprod.o9solutions.com/ Prod : https://myamorepacific.o9solutions.com/
B7: SEQ | C7: Field | D7: PK | E7: Type | F7: Size | G7: Desc | H7: Desc(ENG) | I7: SEQ | J7: Field | K7: PK | L7: Type | M7: Size | N7: Desc | O7: Desc(ENG) | P7: Req No | Q7: Res No | Z7: 컬럼명 | AA7: 데이터타입 | AB7: 한글명 | AC7: 영문명
B8: 1 | C8: I_LEGACY | D8: Y | E8: VARCHAR2 | F8: 10 | G8: Legacy system | H8: Legacy System | I8: 1 | K8: Y | Z8: PRD_CD | AA8: VARCHAR(12) | AB8: 상품코드 | AC8: Product Code.
B9: 2 | C9: KNUMH | D9: Y | E9: VARCHAR2 | F9: 10 | G9: 조건 번호 | H9: Condition number | I9: 2 | J9: ConditionNo | K9: Y | L9: NVARCHAR | M9: 1000 | N9: 조건 번호 | O9: Condition number | Z9: PRD_NM | AA9: VARCHAR(100) | AB9: 상품명 | AC9: Product Name.
B10: 3 | C10: KSCHL | D10: Y | E10: VARCHAR2 | F10: 12 | G10: 조건 유형 | H10: Condition | I10: 3 | J10: ConditionType | K10: Y | L10: NVARCHAR | M10: 1000 | N10: 조건 유형 | O10: Condition | Z10: PRD_ENGL_NM | AA10: VARCHAR(200) | AB10: 상품영어명 | AC10: Product English Name.
B11: 4 | C11: VKORG | D11: Y | E11: VARCHAR2 | F11: 12 | G11: 판매 조직 | H11: Sales organization | I11: 4 | J11: SalesOrg | K11: Y | L11: NVARCHAR | M11: 1000 | N11: 판매 조직 | O11: Sales organization | Z11: ENGL_PRD_NM | AA11: VARCHAR(100) | AB11: 영어상품명(비표준) | AC11: English Product Name (Non-Standard).
B12: 5 | C12: WAERK | D12: Y | E12: VARCHAR2 | F12: 15 | G12: 통화 | H12: Currency | I12: 5 | J12: Currency | K12: Y | L12: NVARCHAR | M12: 1000 | N12: 통화 | O12: Currency | Z12: BRND_CD | AA12: VARCHAR(5) | AB12: 브랜드코드 | AC12: Brand Code.
B13: 6 | C13: MATNR | D13: Y | E13: VARCHAR2 | F13: 54 | G13: 자재 번호 | H13: Material number | I13: 6 | J13: Item | K13: Y | L13: NVARCHAR | M13: 1000 | N13: 자재 번호 | O13: Material number | Z13: BRND_DTL_CD | AA13: VARCHAR(6) | AB13: 브랜드상세코드 | AC13: Brand Detail Code.
B14: 7 | C14: PLTYP | E14: VARCHAR2 | F14: 6 | G14: 가격리스트유형 | H14: Price list type | I14: 7 | J14: PriceListType | L14: NVARCHAR | M14: 1000 | N14: 가격리스트유형 | O14: Price list type | Z14: RPRS_PRD_CD | AA14: VARCHAR(12) | AB14: 대표상품코드 | AC14: Representative Product Code.
B15: 8 | C15: DATBI | E15: VARCHAR2 | F15: 24 | G15: 종료일 | H15: End date | I15: 8 | J15: EffEndDate | L15: NVARCHAR | M15: 1000 | N15: 종료일 | O15: End date | Z15: RPRS_PRD_NM | AA15: VARCHAR(100) | AB15: 대표상품명 | AC15: Product Name.
B16: 9 | C16: DATAB | E16: VARCHAR2 | F16: 24 | G16: 시작일 | H16: start date | I16: 9 | J16: EffStartDate | L16: NVARCHAR | M16: 1000 | N16: 시작일 | O16: start date | Z16: RPRS_PRD_ENGL_NM | AA16: VARCHAR(100) | AB16: 대표상품영어명 | AC16: Representative Product English Name.
B17: 10 | C17: KBETR | E17: NUMBER | F17: 11.2 | G17: 상품대(부가세제외) | H17: Product price (excluding additional tax) | I17: 10 | J17: KBETR | L17: NVARCHAR | M17: 1000 | N17: 상품대(부가세제외) | O17: Product price (excluding additional tax) | Z17: RPLC_PRD_CD | AA17: VARCHAR(12) | AB17: 대체상품코드 | AC17: Alternative Product Code.
B18: 11 | C18: KBETR_INV | E18: NUMBER | F18: 11.2 | G18: 출하가(부가세포함) | H18: Shipping price (additional cell box) | I18: 11 | J18: KBETR_INV | L18: NVARCHAR | M18: 1000 | N18: 출하가(부가세포함) | O18: Shipping price (additional cell box) | Z18: PRD_MKT_CAT_CD | AA18: VARCHAR(2) | AB18: 상품마케팅분류코드 | AC18: Product Marketing Classification Code.
B19: 12 | C19: KBETR_VAT | E19: NUMBER | F19: 11.2 | G19: 부가세 | H19: VAT | I19: 12 | J19: KBETR_VAT | L19: NVARCHAR | M19: 1000 | N19: 부가세 | O19: VAT | Z19: SET_PRD_YN | AA19: VARCHAR(1) | AB19: 세트상품여부 | AC19: Set product or not.
B20: 13 | C20: SPETAX | E20: NUMBER | F20: 11.2 | G20: 특소세(개별소비세+교육세+농어촌특별세) | H20: Special tax (individual consumption tax+education tax+special farming and fishing village) | I20: 13 | J20: SPETAX | L20: NVARCHAR | M20: 1000 | N20: 특소세(개별소비세+교육세+농어촌특별세) | O20: Special tax (individual consumption tax+education tax+special farming and fishing village) | Z20: SET_DSMN_YN | AA20: VARCHAR(1) | AB20: 세트해체여부 | AC20: Set disassembly.
B21: 14 | C21: CONTAX | E21: NUMBER | F21: 11.2 | G21: 개별소비세 | H21: Individual consumption tax | I21: 14 | J21: CONTAX | L21: NVARCHAR | M21: 1000 | N21: 개별소비세 | O21: Individual consumption tax | Z21: CNSM_UTPR_AMT | AA21: NUMBER(20,3) | AB21: 소비자단가금액 | AC21: Consumer Unit Price.
B22: 15 | C22: EDUTAX | E22: NUMBER | F22: 11.2 | G22: 교육세 | H22: Education tax | I22: 15 | J22: EDUTAX | L22: NVARCHAR | M22: 1000 | N22: 교육세 | O22: Education tax | Z22: PRD_CPT | AA22: NUMBER(38,0) | AB22: 상품용량 | AC22: Product Capacity.
B23: 16 | C23: RURTAX | E23: NUMBER | F23: 11.2 | G23: 농어촌특별세 | H23: Special tax | I23: 16 | J23: RURTAX | L23: NVARCHAR | M23: 1000 | N23: 농어촌특별세 | O23: Special tax | Z23: PRD_CPT_UNIT_CD | AA23: VARCHAR(3) | AB23: 상품용량단위코드 | AC23: Product Unit Code.
B24: 17 | C24: LOEVM_KO | E24: VARCHAR2 | F24: 2 | G24: 삭제지시자 | H24: Deleter | I24: 17 | J24: DeleteFlag | L24: NVARCHAR | M24: 1000 | N24: 삭제지시자 | O24: Deleter | Z24: PRD_USE_CD | AA24: VARCHAR(3) | AB24: 상품용도코드 | AC24: Product Use Code.
B25: 18 | C25: GUBUN | E25: VARCHAR2 | F25: 2 | G25: 구분 | H25: division | I25: 18 | J25: Type | L25: NVARCHAR | M25: 1000 | N25: 구분 | O25: division | Z25: PRD_CAT_CD | AA25: VARCHAR(10) | AB25: 상품분류코드 | AC25: Product Classification Code.
B26: 19 | C26: TYPE | E26: CHAR | F26: 1 | G26: 전송결과 S,E | H26: Transmission Result S, E | I26: 19 | Z26: MAIN_FUNC_CD | AA26: VARCHAR(4) | AB26: 주요기능코드 | AC26: Main Function Code.
B27: 20 | C27: MESSAGE | E27: CHAR | F27: 220 | G27: 전송결과 메시지 | H27: Transmission result message | I27: 20 | Z27: USER_TP_CD | AA27: VARCHAR(1) | AB27: 사용자유형코드 | AC27: User Type Code.
B28: 21 | I28: 21 | Z28: FRSH_CSMT_YN | AA28: VARCHAR(1) | AB28: 신선화장품여부 | AC28: Fresh Cosmetics.
B29: 22 | I29: 22 | Z29: PRD_CL_CD | AA29: VARCHAR(2) | AB29: 상품구분코드 | AC29: Product Classification Code.
B30: 23 | I30: 23 | Z30: SLS_TP_CD | AA30: VARCHAR(3) | AB30: 영업유형코드 | AC30: Sales Type Code.
B31: 24 | I31: 24 | Z31: SAP_PRD_LN_CD | AA31: VARCHAR(4) | AB31: SAP상품라인코드 | AC31: SAP Product Line Code.
B32: 25 | I32: 25 | Z32: PRD_CLR_CD | AA32: VARCHAR(4) | AB32: 상품색상코드 | AC32: Product Color Code.
B33: 26 | I33: 26 | Z33: NEW_PRD_CL_CD | AA33: VARCHAR(3) | AB33: 신상품구분코드 | AC33: New Product Code.
B34: 27 | I34: 27 | Z34: STRO_PRD_YN | AA34: VARCHAR(1) | AB34: 강한상품여부 | AC34: Strong product or not.
B35: 28 | I35: 28 | Z35: INNO_PRD_YN | AA35: VARCHAR(1) | AB35: 혁신상품여부 | AC35: Innovative Product Status.
B36: 29 | I36: 29 | Z36: CUSH_PRD_YN | AA36: VARCHAR(1) | AB36: 쿠션상품여부 | AC36: Cushion product status.
B37: 30 | I37: 30 | Z37: PRD_GRD_CD | AA37: VARCHAR(3) | AB37: 상품등급코드 | AC37: Product Grade Code.
B38: 31 | I38: 31 | Z38: BRND_LN_CD | AA38: VARCHAR(4) | AB38: 브랜드라인코드 | AC38: Brand Line Code.
Z39: MFG_PLNT_CD | AA39: VARCHAR(4) | AB39: 생산플랜트코드 | AC39: Production Plant Code.
Z40: NITM_APLY_YN | AA40: VARCHAR(1) | AB40: 품목수적용여부 | AC40: Item Application.
...

Sheet NPD자재목록
A1: Top
B2: 매핑정의서 - NPD자재목록(NPD material list) | J2: Source System | K2: NPD | O2: 문서작성일 | P2: 2025.09.25
J3: Target System | K3: APLAN | O3: 버전 | P3: 0.1
B4: 매핑정의
B5: Source Table : ? | I5: Target Table : ? | R5: Set Value | S5: 변환 규칙 | Z5: CDP 자재 마스터 테이블 명세서 (D_PRD_MSTR)
B6: RFC | I6: Web SVC | J6: PreProd : https://myamorepacificpreprod.o9solutions.com/ Prod : https://myamorepacific.o9solutions.com/
B7: SEQ | C7: Field | D7: PK | E7: Type | F7: Size | G7: Desc | H7: Desc(ENG) | I7: SEQ | J7: Field | K7: PK | L7: Type | M7: Size | N7: Desc | O7: Desc(ENG) | P7: Req No | Q7: Res No | Z7: 컬럼명 | AA7: 데이터타입 | AB7: 한글명 | AC7: 영문명
B8: 1 | C8: I_TERMS_F | D8: Y | E8: CHAR | F8: 8 | G8: 시작일 FROM | H8: From Date | I8: 1 | J8: FROM | K8: Y | L8: NVARCHAR | M8: 1000 | N8: From Date("20221001") | O8: From Date | Z8: PRD_CD | AA8: VARCHAR(12) | AB8: 상품코드 | AC8: Product Code.
B9: 2 | C9: I_TERMS_T | D9: Y | E9: CHAR | F9: 8 | G9: 종료일 TO | H9: To Date | I9: 2 | J9: TO | K9: Y | L9: NVARCHAR | M9: 1000 | N9: To Date | O9: To Date | Z9: PRD_NM | AA9: VARCHAR(100) | AB9: 상품명 | AC9: Product Name.
B10: 3 | C10: DEVNO | D10: Y | E10: CHAR | F10: 12 | G10: 개발의뢰서번호 | H10: Development request number | I10: 3 | J10: DevNo | K10: Y | L10: NVARCHAR | M10: 1000 | N10: 개발의뢰서번호 | O10: Development request number | Z10: PRD_ENGL_NM | AA10: VARCHAR(200) | AB10: 상품영어명 | AC10: Product English Name.
B11: 4 | C11: MATNR | D11: Y | E11: CHAR | F11: 18 | G11: 제품코드 | H11: Product code | I11: 4 | J11: Item | K11: Y | L11: NVARCHAR | M11: 1000 | N11: 제품코드 | O11: Product code | Z11: ENGL_PRD_NM | AA11: VARCHAR(100) | AB11: 영어상품명(비표준) | AC11: English Product Name (Non-Standard).
B12: 5 | C12: YYMM | E12: CHAR | F12: 6 | G12: 생산회의년월( ex: 201709 ) | H12: Production meeting month (ex: 201709) | I12: 5 | J12: YYYYMM | L12: NVARCHAR | M12: 1000 | N12: 생산회의년월( ex: 201709 ) | O12: Production meeting month (ex: 201709) | Z12: BRND_CD | AA12: VARCHAR(5) | AB12: 브랜드코드 | AC12: Brand Code.
B13: 6 | C13: DEGREE | E13: CHAR | F13: 1 | G13: 주차(1,2,3,4) | H13: Week | I13: 6 | J13: Week | L13: NVARCHAR | M13: 1000 | N13: 주차(1,2,3,4) | O13: Week | Z13: BRND_DTL_CD | AA13: VARCHAR(6) | AB13: 브랜드상세코드 | AC13: Brand Detail Code.
B14: 7 | C14: ZZMANFT | E14: CHAR | F14: 4 | G14: 플랜트코드 | H14: Plant code | I14: 7 | J14: Plant | L14: NVARCHAR | M14: 1000 | N14: 플랜트코드 | O14: Plant code | Z14: RPRS_PRD_CD | AA14: VARCHAR(12) | AB14: 대표상품코드 | AC14: Representative Product Code.
B15: 8 | C15: MTBC | E15: CHAR | F15: 1 | G15: [NPD] 생산회의상정확인( X:확인, ‘’: 미확인 ) | H15: Production meeting Confirmation (X: OK, '': Unidentified) | I15: 8 | J15: NPDMeetFlag | L15: NVARCHAR | M15: 1000 | N15: [NPD] 생산회의상정확인( X:확인, ‘’: 미확인 ) | O15: Production meeting Confirmation (X: OK, '': Unidentified) | Z15: RPRS_PRD_NM | AA15: VARCHAR(100) | AB15: 대표상품명 | AC15: Product Name.
B16: 9 | C16: LVORM | E16: CHAR | F16: 1 | G16: 삭제여부(개발의뢰서 삭제하는경우( X:삭제, ‘’: 미삭제 ) | H16: Deletion (X: delete, ‘’: Undeleted ) | I16: 9 | J16: DeleteFlag | L16: NVARCHAR | M16: 1000 | N16: 삭제여부(개발의뢰서 삭제하는경우( X:삭제, ‘’: 미삭제 ) | O16: Deletion (X: delete, ‘’: Undeleted ) | Z16: RPRS_PRD_ENGL_NM | AA16: VARCHAR(100) | AB16: 대표상품영어명 | AC16: Representative Product English Name.
B17: 10 | I17: 10 | Z17: RPLC_PRD_CD | AA17: VARCHAR(12) | AB17: 대체상품코드 | AC17: Alternative Product Code.
B18: 11 | I18: 11 | Z18: PRD_MKT_CAT_CD | AA18: VARCHAR(2) | AB18: 상품마케팅분류코드 | AC18: Product Marketing Classification Code.
B19: 12 | I19: 12 | Z19: SET_PRD_YN | AA19: VARCHAR(1) | AB19: 세트상품여부 | AC19: Set product or not.
B20: 13 | I20: 13 | Z20: SET_DSMN_YN | AA20: VARCHAR(1) | AB20: 세트해체여부 | AC20: Set disassembly.
B21: 14 | I21: 14 | Z21: CNSM_UTPR_AMT | AA21: NUMBER(20,3) | AB21: 소비자단가금액 | AC21: Consumer Unit Price.
B22: 15 | I22: 15 | Z22: PRD_CPT | AA22: NUMBER(38,0) | AB22: 상품용량 | AC22: Product Capacity.
B23: 16 | I23: 16 | Z23: PRD_CPT_UNIT_CD | AA23: VARCHAR(3) | AB23: 상품용량단위코드 | AC23: Product Unit Code.
B24: 17 | I24: 17 | Z24: PRD_USE_CD | AA24: VARCHAR(3) | AB24: 상품용도코드 | AC24: Product Use Code.
B25: 18 | I25: 18 | Z25: PRD_CAT_CD | AA25: VARCHAR(10) | AB25: 상품분류코드 | AC25: Product Classification Code.
B26: 19 | I26: 19 | Z26: MAIN_FUNC_CD | AA26: VARCHAR(4) | AB26: 주요기능코드 | AC26: Main Function Code.
B27: 20 | I27: 20 | Z27: USER_TP_CD | AA27: VARCHAR(1) | AB27: 사용자유형코드 | AC27: User Type Code.
B28: 21 | I28: 21 | Z28: FRSH_CSMT_YN | AA28: VARCHAR(1) | AB28: 신선화장품여부 | AC28: Fresh Cosmetics.
... B38: 31 | I38: 31 | Z38: BRND_LN_CD | AA38: VARCHAR(4) | AB38: 브랜드라인코드 | AC38: Brand Line Code.
Z39: MFG_PLNT_CD | AA39: VARCHAR(4) | AB39: 생산플랜트코드 | AC39: Production Plant Code.
Z40: NITM_APLY_YN | AA40: VARCHAR(1) | AB40: 품목수적용여부 | AC40: Item Application.
B41: 변환규칙정의 | Z41: FST_MFG_DT | AA41: VARCHAR(10) | AB41: 최초생산일자 | AC41: Initial Production Date.
B42: 변환규칙 | D42: 내용 | Z42: LST_MFG_DT | AA42: VARCHAR(10) | AB42: 최종생산일자 | AC42: Final production date.
B43: R1 | Z43: PRD_BRCD_CD | AA43: VARCHAR(15) | AB43: 상품바코드코드 | AC43: Product barcode code.
B44: R2 | Z44: REG_APPL_CL_CD | AA44: VARCHAR(10) | AB44: 등록어플리케이션구분코드 | AC44: Registration Application Type Code.
Z45: CP_PRD_YN | AA45: VARCHAR(1) | AB45: 자사상품여부 | AC45: Is it a company product?.
B46: 기타정보 | Z46: INSD_MGNT_AMT | AA46: NUMBER(20,3) | AB46: 내부관리금액 | AC46: Internal Management Amount.
B47: 이벤트 발생조건 (DB Trigger) | Z47: WKPL_CL_CD | AA47: VARCHAR(10) | AB47: 사업장구분코드 | AC47: Business Site Classification Code.
B48: 연계데이터 추출조건 | Z48: ASRC_PRD_MKT_CAT_CD | AA48: VARCHAR(2) | AB48: 소스상품마케팅분류코드 | AC48: Source Product Marketing Classification Code.
B49: 데이터 반영방법 | Z49: ASRC_PRD_CAT_CD | AA49: VARCHAR(10) | AB49: 소스상품분류코드 | AC49: Source Product Classification Code.
...

Sheet 제품허가정보
A1: Top
B2: 매핑정의서 - 제품허가정보 관리 Product License Information | J2: Source System | K2: SAP | O2: 문서작성일 | P2: 2025.09.25
J3: Target System | K3: APLAN | O3: 버전 | P3: 0.1
B4: 매핑정의
B5: Source Table : ? | I5: Target Table : ? | R5: Set Value | S5: 변환 규칙 | Z5: CDP 자재 마스터 테이블 명세서 (D_PRD_MSTR)
